Exception in callback future.<locals>.callback(<Task cancell...ulers.py:149>>) at /Users/sach/miniconda3/envs/deeplearning/lib/python3.9/site-packages/dawgz/utils.py:77
handle: <Handle future.<locals>.callback(<Task cancell...ulers.py:149>>) at /Users/sach/miniconda3/envs/deeplearning/lib/python3.9/site-packages/dawgz/utils.py:77>
Traceback (most recent call last):
  File "/Users/sach/miniconda3/envs/deeplearning/lib/python3.9/asyncio/runners.py", line 44, in run
    return loop.run_until_complete(main)
  File "/Users/sach/miniconda3/envs/deeplearning/lib/python3.9/asyncio/base_events.py", line 634, in run_until_complete
    self.run_forever()
  File "/Users/sach/miniconda3/envs/deeplearning/lib/python3.9/asyncio/base_events.py", line 601, in run_forever
    self._run_once()
  File "/Users/sach/miniconda3/envs/deeplearning/lib/python3.9/asyncio/base_events.py", line 1869, in _run_once
    event_list = self._selector.select(timeout)
  File "/Users/sach/miniconda3/envs/deeplearning/lib/python3.9/selectors.py", line 562, in select
    kev_list = self._selector.control(None, max_ev, timeout)
KeyboardInterrupt
During handling of the above exception, another exception occurred:
Traceback (most recent call last):
  File "/Users/sach/miniconda3/envs/deeplearning/lib/python3.9/site-packages/dawgz/schedulers.py", line 158, in _submit
    return await self.exec(job)
  File "/Users/sach/miniconda3/envs/deeplearning/lib/python3.9/site-packages/dawgz/schedulers.py", line 258, in exec
    return await call()
  File "/Users/sach/miniconda3/envs/deeplearning/lib/python3.9/site-packages/dawgz/schedulers.py", line 271, in remote
    return await asyncio.get_running_loop().run_in_executor(self.executor, f, *args)
asyncio.exceptions.CancelledError
During handling of the above exception, another exception occurred:
Traceback (most recent call last):
  File "/Users/sach/miniconda3/envs/deeplearning/lib/python3.9/asyncio/events.py", line 80, in _run
    self._context.run(self._callback, *self._args)
  File "/Users/sach/miniconda3/envs/deeplearning/lib/python3.9/site-packages/dawgz/utils.py", line 78, in callback
    result = self.exception()
asyncio.exceptions.CancelledError
Traceback (most recent call last):
  File "/Users/sach/Development/Python/VANO/experiments/2d_gaussian_pdf.py", line 233, in <module>
  File "/Users/sach/miniconda3/envs/deeplearning/lib/python3.9/site-packages/dawgz/schedulers.py", line 192, in schedule
    scheduler.wait(*jobs)
  File "/Users/sach/miniconda3/envs/deeplearning/lib/python3.9/site-packages/dawgz/schedulers.py", line 128, in wait
    asyncio.run(self._wait(*jobs))
  File "/Users/sach/miniconda3/envs/deeplearning/lib/python3.9/asyncio/runners.py", line 44, in run
    return loop.run_until_complete(main)
  File "/Users/sach/miniconda3/envs/deeplearning/lib/python3.9/asyncio/base_events.py", line 634, in run_until_complete
    self.run_forever()
  File "/Users/sach/miniconda3/envs/deeplearning/lib/python3.9/asyncio/base_events.py", line 601, in run_forever
    self._run_once()
  File "/Users/sach/miniconda3/envs/deeplearning/lib/python3.9/asyncio/base_events.py", line 1869, in _run_once
    event_list = self._selector.select(timeout)
  File "/Users/sach/miniconda3/envs/deeplearning/lib/python3.9/selectors.py", line 562, in select
    kev_list = self._selector.control(None, max_ev, timeout)
KeyboardInterrupt
Traceback (most recent call last):
  File "/Users/sach/Development/Python/VANO/experiments/2d_gaussian_pdf.py", line 233, in <module>
  File "/Users/sach/miniconda3/envs/deeplearning/lib/python3.9/site-packages/dawgz/schedulers.py", line 192, in schedule
    scheduler.wait(*jobs)
  File "/Users/sach/miniconda3/envs/deeplearning/lib/python3.9/site-packages/dawgz/schedulers.py", line 128, in wait
    asyncio.run(self._wait(*jobs))
  File "/Users/sach/miniconda3/envs/deeplearning/lib/python3.9/asyncio/runners.py", line 44, in run
    return loop.run_until_complete(main)
  File "/Users/sach/miniconda3/envs/deeplearning/lib/python3.9/asyncio/base_events.py", line 634, in run_until_complete
    self.run_forever()
  File "/Users/sach/miniconda3/envs/deeplearning/lib/python3.9/asyncio/base_events.py", line 601, in run_forever
    self._run_once()
  File "/Users/sach/miniconda3/envs/deeplearning/lib/python3.9/asyncio/base_events.py", line 1869, in _run_once
    event_list = self._selector.select(timeout)
  File "/Users/sach/miniconda3/envs/deeplearning/lib/python3.9/selectors.py", line 562, in select
    kev_list = self._selector.control(None, max_ev, timeout)
KeyboardInterrupt
Exception ignored in: <module 'threading' from '/Users/sach/miniconda3/envs/deeplearning/lib/python3.9/threading.py'>
Traceback (most recent call last):
  File "/Users/sach/miniconda3/envs/deeplearning/lib/python3.9/threading.py", line 1447, in _shutdown
    atexit_call()
  File "/Users/sach/miniconda3/envs/deeplearning/lib/python3.9/concurrent/futures/thread.py", line 31, in _python_exit
    t.join()
  File "/Users/sach/miniconda3/envs/deeplearning/lib/python3.9/threading.py", line 1060, in join
    self._wait_for_tstate_lock()
  File "/Users/sach/miniconda3/envs/deeplearning/lib/python3.9/threading.py", line 1080, in _wait_for_tstate_lock
    if lock.acquire(block, timeout):
KeyboardInterrupt: